
<?xml version="1.0"?>
<robot name="my_robot">

  <!-- Cube base link -->
  <link name="base_link">
    <inertial>
      <mass value="1"/>
      <inertia ixx="1" ixy="0" ixz="0" iyy="1" iyz="0" izz="1"/>
    </inertial>
    <visual>
      <origin xyz="0 0 0.5" rpy="0 0 0"/>
      <geometry>
        <box size="1 1 1"/>
      </geometry>
      <material name="white"/>
    </visual>
    <collision>
      <origin xyz="0 0 0.5" rpy="0 0 0"/>
      <geometry>
        <box size="1 1 1"/>
      </geometry>
    </collision>
  </link>

  <gazebo reference="base_link"> 
    <material>Gazebo/White</material> 
  </gazebo>

  <!-- Joint between cube and balloon -->
  <joint name="balloon_joint" type="prismatic">
    <origin xyz="0 0 3.0" rpy="0 -1.57 0" /> 
    <parent link="base_link" /> 
    <child link="balloon_link"/>
    <limit lower="-3" upper="10" effort="10" velocity="5"/>
    <gravity>0</gravity>
  </joint>

  <gazebo reference="balloon_joint"/>

  <!-- Balloon link --> 
  <link name="balloon_link">
    <inertial>
      <mass value="1"/> 
      <inertia ixx="1" ixy="0" ixz="0" iyy="1" iyz="0" izz="1"/> 
    </inertial> 
    <visual> 
      <origin xyz="1 0 0" rpy="0 0 0" /> 
      <geometry> 
        <sphere radius="1" /> 
      </geometry> 
      <material name="blue" /> 
    </visual>
    <gravity>0</gravity>
    <collision> 
       <origin xyz="1 0 0" rpy="0 0 0" /> 
      <geometry> 
        <sphere radius="1" /> 
      </geometry>
    </collision> 
  </link>

 <gazebo reference="balloon_link"> 
    <material>Gazebo/Blue</material> 
    <gravity>0</gravity> 
  </gazebo>

</robot>